2022-06-02 13:11:40,312: [14] m.main:INFO: Registered plugins: IntrospectionAPIPlugin, <class 'manticore.ethereum.plugins.SkipRevertBasicBlocks'>, <class 'manticore.ethereum.plugins.FilterFunctions'>
2022-06-02 13:11:40,313: [14] m.main:INFO: Beginning analysis
2022-06-02 13:11:40,316: [14] m.e.manticore:INFO: Starting symbolic create contract
2022-06-02 13:11:41,517: [14] m.e.manticore:INFO: Starting symbolic transaction: 0
2022-06-02 13:11:52,049: [14] m.c.worker:ERROR: Exception in state 6: ManticoreError('Forking on unfeasible constraint set')
Traceback (most recent call last):
  File "/usr/local/lib/python3.7/dist-packages/manticore/core/worker.py", line 137, in run
    current_state.execute()
  File "/usr/local/lib/python3.7/dist-packages/manticore/ethereum/state.py", line 8, in execute
    return self._platform.execute()
  File "/usr/local/lib/python3.7/dist-packages/manticore/platforms/evm.py", line 3106, in execute
    self.current_vm.execute()
  File "/usr/local/lib/python3.7/dist-packages/manticore/platforms/evm.py", line 1322, in execute
    raise Concretize("Symbolic PC", expression=expression, setstate=setstate, policy="ALL")
manticore.core.state.Concretize

During handling of the above exception, another exception occurred:

Traceback (most recent call last):
  File "/usr/local/lib/python3.7/dist-packages/manticore/core/worker.py", line 158, in run
    m._fork(current_state, exc.expression, exc.policy, exc.setstate, exc.values)
  File "/usr/local/lib/python3.7/dist-packages/manticore/core/manticore.py", line 518, in _fork
    raise ManticoreError("Forking on unfeasible constraint set")
manticore.exceptions.ManticoreError: Forking on unfeasible constraint set
 
2022-06-02 13:11:54,018: [14] m.e.manticore:INFO: 1 alive states, 2 terminated states
2022-06-02 13:11:54,350: [14] m.e.manticore:INFO: Starting symbolic transaction: 1
2022-06-02 13:12:05,049: [14] m.c.worker:ERROR: Exception in state 4: ManticoreError('Forking on unfeasible constraint set')
Traceback (most recent call last):
  File "/usr/local/lib/python3.7/dist-packages/manticore/core/worker.py", line 137, in run
    current_state.execute()
  File "/usr/local/lib/python3.7/dist-packages/manticore/ethereum/state.py", line 8, in execute
    return self._platform.execute()
  File "/usr/local/lib/python3.7/dist-packages/manticore/platforms/evm.py", line 3106, in execute
    self.current_vm.execute()
  File "/usr/local/lib/python3.7/dist-packages/manticore/platforms/evm.py", line 1322, in execute
    raise Concretize("Symbolic PC", expression=expression, setstate=setstate, policy="ALL")
manticore.core.state.Concretize

During handling of the above exception, another exception occurred:

Traceback (most recent call last):
  File "/usr/local/lib/python3.7/dist-packages/manticore/core/worker.py", line 158, in run
    m._fork(current_state, exc.expression, exc.policy, exc.setstate, exc.values)
  File "/usr/local/lib/python3.7/dist-packages/manticore/core/manticore.py", line 518, in _fork
    raise ManticoreError("Forking on unfeasible constraint set")
manticore.exceptions.ManticoreError: Forking on unfeasible constraint set
 
2022-06-02 13:12:05,898: [14] m.e.manticore:INFO: 1 alive states, 3 terminated states
2022-06-02 13:12:06,398: [14] m.e.manticore:INFO: Starting symbolic transaction: 2
2022-06-02 13:12:17,873: [14] m.c.worker:ERROR: Exception in state 1: ManticoreError('Forking on unfeasible constraint set')
Traceback (most recent call last):
  File "/usr/local/lib/python3.7/dist-packages/manticore/core/worker.py", line 137, in run
    current_state.execute()
  File "/usr/local/lib/python3.7/dist-packages/manticore/ethereum/state.py", line 8, in execute
    return self._platform.execute()
  File "/usr/local/lib/python3.7/dist-packages/manticore/platforms/evm.py", line 3106, in execute
    self.current_vm.execute()
  File "/usr/local/lib/python3.7/dist-packages/manticore/platforms/evm.py", line 1322, in execute
    raise Concretize("Symbolic PC", expression=expression, setstate=setstate, policy="ALL")
manticore.core.state.Concretize

During handling of the above exception, another exception occurred:

Traceback (most recent call last):
  File "/usr/local/lib/python3.7/dist-packages/manticore/core/worker.py", line 158, in run
    m._fork(current_state, exc.expression, exc.policy, exc.setstate, exc.values)
  File "/usr/local/lib/python3.7/dist-packages/manticore/core/manticore.py", line 518, in _fork
    raise ManticoreError("Forking on unfeasible constraint set")
manticore.exceptions.ManticoreError: Forking on unfeasible constraint set
 
2022-06-02 13:12:18,949: [14] m.e.manticore:INFO: 1 alive states, 4 terminated states
2022-06-02 13:12:19,732: [109] m.c.manticore:INFO: Generated testcase No. 0 - STOP(4 txs)
2022-06-02 13:12:19,734: [109] m.c.plugin:WARNING: Caught will_solve in state None, but failed to capture its initialization
2022-06-02 13:12:23,281: [14] m.c.manticore:INFO: Results in /mcore_hvpr59et
2022-06-02 13:12:23,281: [14] m.c.manticore:INFO: Total time: 16.855600833892822