2023-01-17 17:43:25,112: [12] m.main:INFO: Registered plugins: IntrospectionAPIPlugin, <class 'manticore.ethereum.plugins.SkipRevertBasicBlocks'>, <class 'manticore.ethereum.plugins.FilterFunctions'>
2023-01-17 17:43:25,113: [12] m.main:INFO: Beginning analysis
2023-01-17 17:43:25,116: [12] m.e.manticore:INFO: Starting symbolic create contract
2023-01-17 17:43:26,166: [12] m.e.manticore:INFO: Starting symbolic transaction: 0
2023-01-17 17:43:36,287: [12] m.c.worker:ERROR: Exception in state 1: ManticoreError('Forking on unfeasible constraint set')
Traceback (most recent call last):
  File "/usr/local/lib/python3.7/dist-packages/manticore/core/worker.py", line 137, in run
    current_state.execute()
  File "/usr/local/lib/python3.7/dist-packages/manticore/ethereum/state.py", line 8, in execute
    return self._platform.execute()
  File "/usr/local/lib/python3.7/dist-packages/manticore/platforms/evm.py", line 3106, in execute
    self.current_vm.execute()
  File "/usr/local/lib/python3.7/dist-packages/manticore/platforms/evm.py", line 1322, in execute
    raise Concretize("Symbolic PC", expression=expression, setstate=setstate, policy="ALL")
manticore.core.state.Concretize

During handling of the above exception, another exception occurred:

Traceback (most recent call last):
  File "/usr/local/lib/python3.7/dist-packages/manticore/core/worker.py", line 158, in run
    m._fork(current_state, exc.expression, exc.policy, exc.setstate, exc.values)
  File "/usr/local/lib/python3.7/dist-packages/manticore/core/manticore.py", line 518, in _fork
    raise ManticoreError("Forking on unfeasible constraint set")
manticore.exceptions.ManticoreError: Forking on unfeasible constraint set
 
2023-01-17 17:43:38,613: [12] m.e.manticore:INFO: 1 alive states, 2 terminated states
2023-01-17 17:43:39,114: [12] m.e.manticore:INFO: Starting symbolic transaction: 1
2023-01-17 17:43:52,857: [12] m.c.worker:ERROR: Exception in state 2: ManticoreError('Forking on unfeasible constraint set')
Traceback (most recent call last):
  File "/usr/local/lib/python3.7/dist-packages/manticore/core/worker.py", line 137, in run
    current_state.execute()
  File "/usr/local/lib/python3.7/dist-packages/manticore/ethereum/state.py", line 8, in execute
    return self._platform.execute()
  File "/usr/local/lib/python3.7/dist-packages/manticore/platforms/evm.py", line 3106, in execute
    self.current_vm.execute()
  File "/usr/local/lib/python3.7/dist-packages/manticore/platforms/evm.py", line 1322, in execute
    raise Concretize("Symbolic PC", expression=expression, setstate=setstate, policy="ALL")
manticore.core.state.Concretize

During handling of the above exception, another exception occurred:

Traceback (most recent call last):
  File "/usr/local/lib/python3.7/dist-packages/manticore/core/worker.py", line 158, in run
    m._fork(current_state, exc.expression, exc.policy, exc.setstate, exc.values)
  File "/usr/local/lib/python3.7/dist-packages/manticore/core/manticore.py", line 518, in _fork
    raise ManticoreError("Forking on unfeasible constraint set")
manticore.exceptions.ManticoreError: Forking on unfeasible constraint set
 
2023-01-17 17:43:54,688: [12] m.e.manticore:INFO: 1 alive states, 3 terminated states
2023-01-17 17:43:55,225: [12] m.e.manticore:INFO: Starting symbolic transaction: 2
2023-01-17 17:44:09,485: [12] m.c.worker:ERROR: Exception in state 11: ManticoreError('Forking on unfeasible constraint set')
Traceback (most recent call last):
  File "/usr/local/lib/python3.7/dist-packages/manticore/core/worker.py", line 137, in run
    current_state.execute()
  File "/usr/local/lib/python3.7/dist-packages/manticore/ethereum/state.py", line 8, in execute
    return self._platform.execute()
  File "/usr/local/lib/python3.7/dist-packages/manticore/platforms/evm.py", line 3106, in execute
    self.current_vm.execute()
  File "/usr/local/lib/python3.7/dist-packages/manticore/platforms/evm.py", line 1322, in execute
    raise Concretize("Symbolic PC", expression=expression, setstate=setstate, policy="ALL")
manticore.core.state.Concretize

During handling of the above exception, another exception occurred:

Traceback (most recent call last):
  File "/usr/local/lib/python3.7/dist-packages/manticore/core/worker.py", line 158, in run
    m._fork(current_state, exc.expression, exc.policy, exc.setstate, exc.values)
  File "/usr/local/lib/python3.7/dist-packages/manticore/core/manticore.py", line 518, in _fork
    raise ManticoreError("Forking on unfeasible constraint set")
manticore.exceptions.ManticoreError: Forking on unfeasible constraint set
 
2023-01-17 17:44:12,966: [12] m.e.manticore:INFO: 1 alive states, 4 terminated states
2023-01-17 17:44:13,863: [107] m.c.manticore:INFO: Generated testcase No. 0 - STOP(4 txs)
2023-01-17 17:44:13,865: [107] m.c.plugin:WARNING: Caught will_solve in state None, but failed to capture its initialization
2023-01-17 17:44:18,763: [12] m.c.manticore:INFO: Results in /mcore_sak4pkke
2023-01-17 17:44:18,764: [12] m.c.manticore:INFO: Total time: 23.492969274520874
