2022-05-31 13:46:20,972: [14] m.main:INFO: Registered plugins: DetectUnusedRetVal, DetectReentrancySimple, DetectInvalid, DetectSuicidal, DetectReentrancyAdvanced, DetectUninitializedStorage, DetectEnvInstruction, DetectDelegatecall, DetectIntegerOverflow, DetectUninitializedMemory, DetectExternalCallAndLeak
2022-05-31 13:46:20,973: [14] m.main:INFO: Beginning analysis
2022-05-31 13:46:20,987: [14] m.e.manticore:INFO: Starting symbolic create contract
2022-05-31 13:46:22,672: [14] m.e.manticore:INFO: Starting symbolic transaction: 0
2022-05-31 13:46:28,872: [333] m.c.worker:ERROR: Exception in state 8: ManticoreError('Forking on unfeasible constraint set',)
Traceback (most recent call last):
  File "/usr/local/lib/python3.6/dist-packages/manticore/platforms/evm.py", line 1213, in execute
    result = self._handler(*arguments)
  File "/usr/local/lib/python3.6/dist-packages/manticore/platforms/evm.py", line 1086, in _handler
    return implementation(*arguments)
  File "/usr/local/lib/python3.6/dist-packages/manticore/platforms/evm.py", line 602, in _pre_func
    self._pre(my_obj, *args, **kwargs)
  File "/usr/local/lib/python3.6/dist-packages/manticore/platforms/evm.py", line 547, in wrapper
    raise ConcretizeArgument(index, policy=policy)
manticore.platforms.evm.ConcretizeArgument: 2

During handling of the above exception, another exception occurred:

Traceback (most recent call last):
  File "/usr/local/lib/python3.6/dist-packages/manticore/core/worker.py", line 121, in run
    current_state.execute()
  File "/usr/local/lib/python3.6/dist-packages/manticore/ethereum/state.py", line 6, in execute
    return self._platform.execute()
  File "/usr/local/lib/python3.6/dist-packages/manticore/platforms/evm.py", line 2684, in execute
    self.current_vm.execute()
  File "/usr/local/lib/python3.6/dist-packages/manticore/platforms/evm.py", line 1279, in execute
    policy=ex.policy,
manticore.core.state.Concretize

During handling of the above exception, another exception occurred:

Traceback (most recent call last):
  File "/usr/local/lib/python3.6/dist-packages/manticore/core/worker.py", line 142, in run
    m._fork(current_state, exc.expression, exc.policy, exc.setstate)
  File "/usr/local/lib/python3.6/dist-packages/manticore/core/manticore.py", line 335, in _fork
    raise ManticoreError("Forking on unfeasible constraint set")
manticore.exceptions.ManticoreError: Forking on unfeasible constraint set
 
2022-05-31 13:46:32,167: [316] m.c.worker:ERROR: Exception in state 3: ManticoreError('Forking on unfeasible constraint set',)
Traceback (most recent call last):
  File "/usr/local/lib/python3.6/dist-packages/manticore/platforms/evm.py", line 1213, in execute
    result = self._handler(*arguments)
  File "/usr/local/lib/python3.6/dist-packages/manticore/platforms/evm.py", line 1086, in _handler
    return implementation(*arguments)
  File "/usr/local/lib/python3.6/dist-packages/manticore/platforms/evm.py", line 602, in _pre_func
    self._pre(my_obj, *args, **kwargs)
  File "/usr/local/lib/python3.6/dist-packages/manticore/platforms/evm.py", line 547, in wrapper
    raise ConcretizeArgument(index, policy=policy)
manticore.platforms.evm.ConcretizeArgument: 2

During handling of the above exception, another exception occurred:

Traceback (most recent call last):
  File "/usr/local/lib/python3.6/dist-packages/manticore/core/worker.py", line 121, in run
    current_state.execute()
  File "/usr/local/lib/python3.6/dist-packages/manticore/ethereum/state.py", line 6, in execute
    return self._platform.execute()
  File "/usr/local/lib/python3.6/dist-packages/manticore/platforms/evm.py", line 2684, in execute
    self.current_vm.execute()
  File "/usr/local/lib/python3.6/dist-packages/manticore/platforms/evm.py", line 1279, in execute
    policy=ex.policy,
manticore.core.state.Concretize

During handling of the above exception, another exception occurred:

Traceback (most recent call last):
  File "/usr/local/lib/python3.6/dist-packages/manticore/core/worker.py", line 142, in run
    m._fork(current_state, exc.expression, exc.policy, exc.setstate)
  File "/usr/local/lib/python3.6/dist-packages/manticore/core/manticore.py", line 335, in _fork
    raise ManticoreError("Forking on unfeasible constraint set")
manticore.exceptions.ManticoreError: Forking on unfeasible constraint set
 
2022-05-31 13:46:32,416: [14] m.e.manticore:INFO: 0 alive states, 4 terminated states
2022-05-31 13:46:33,643: [14] m.e.manticore:INFO: Starting symbolic transaction: 1
2022-05-31 13:46:34,012: [1590] m.c.manticore:INFO: Generated testcase No. 0 - RETURN(1 txs)
2022-05-31 13:46:34,083: [1596] m.c.manticore:INFO: Generated testcase No. 1 - REVERT(2 txs)
2022-05-31 13:46:34,096: [1599] m.c.manticore:INFO: Generated testcase No. 2 - REVERT(2 txs)
2022-05-31 13:46:34,137: [1609] m.c.manticore:INFO: Generated testcase No. 3 - REVERT(2 txs)
2022-05-31 13:46:34,147: [1606] m.c.manticore:INFO: Generated testcase No. 4 - RETURN(1 txs)
2022-05-31 13:46:34,177: [1602] m.c.manticore:INFO: Generated testcase No. 5 - RETURN(1 txs)
Process Process-26:
Traceback (most recent call last):
  File "/usr/lib/python3.6/multiprocessing/process.py", line 258, in _bootstrap
    self.run()
  File "/usr/lib/python3.6/multiprocessing/process.py", line 93, in run
    self._target(*self._args, **self._kwargs)
  File "/usr/local/lib/python3.6/dist-packages/manticore/ethereum/manticore.py", line 1656, in worker_finalize
    finalizer(q.get_nowait())
  File "/usr/local/lib/python3.6/dist-packages/manticore/ethereum/manticore.py", line 1651, in finalizer
    self.generate_testcase(st, message=message)
  File "/usr/local/lib/python3.6/dist-packages/manticore/ethereum/manticore.py", line 1539, in generate_testcase
    is_something_symbolic = state.platform.dump(stream, state, self, message)
  File "/usr/local/lib/python3.6/dist-packages/manticore/platforms/evm.py", line 2972, in dump
    balance = state.solve_one(balance)
  File "/usr/local/lib/python3.6/dist-packages/manticore/core/state.py", line 320, in solve_one
    value = self._solver.get_value(self._constraints, expr)
  File "/usr/local/lib/python3.6/dist-packages/manticore/core/smtlib/solver.py", line 557, in get_value
    raise SolverError("Model is not available")
manticore.exceptions.SolverError: Model is not available
Process Process-25:
Traceback (most recent call last):
  File "/usr/lib/python3.6/multiprocessing/process.py", line 258, in _bootstrap
    self.run()
  File "/usr/lib/python3.6/multiprocessing/process.py", line 93, in run
    self._target(*self._args, **self._kwargs)
  File "/usr/local/lib/python3.6/dist-packages/manticore/ethereum/manticore.py", line 1656, in worker_finalize
    finalizer(q.get_nowait())
  File "/usr/local/lib/python3.6/dist-packages/manticore/ethereum/manticore.py", line 1651, in finalizer
    self.generate_testcase(st, message=message)
  File "/usr/local/lib/python3.6/dist-packages/manticore/ethereum/manticore.py", line 1539, in generate_testcase
    is_something_symbolic = state.platform.dump(stream, state, self, message)
  File "/usr/local/lib/python3.6/dist-packages/manticore/platforms/evm.py", line 2972, in dump
    balance = state.solve_one(balance)
  File "/usr/local/lib/python3.6/dist-packages/manticore/core/state.py", line 320, in solve_one
    value = self._solver.get_value(self._constraints, expr)
  File "/usr/local/lib/python3.6/dist-packages/manticore/core/smtlib/solver.py", line 557, in get_value
    raise SolverError("Model is not available")
manticore.exceptions.SolverError: Model is not available
2022-05-31 13:46:37,475: [14] m.c.manticore:INFO: Results in /mcore_ie16f5kh